<?xml version="1.0" ?>
<!-- =================================================================================== -->
<!-- |    This document was autogenerated by xacro from car_mapper.xacro               | -->
<!-- |    EDITING THIS FILE BY HAND IS NOT RECOMMENDED                                 | -->
<!-- =================================================================================== -->
<robot name="rc_car">
  <material name="orange">
    <color rgba="1 .64  0  1"/>
  </material>
  <material name="black">
    <color rgba="1 1 1 1"/>
  </material>
  <!-- Dummy link -->
  <link name="dummy">
 </link>
  <!-- Inertial Macro -->
  <!-- Chassis Link Definition -->
  <link name="chassis">
    <visual>
      <origin rpy="0 0 0" xyz="0 0 0.09075"/>
      <geometry>
        <mesh filename="package://rc_car/meshes/Chassis.dae"/>
      </geometry>
      <!--  <material name="orange"/>  Uncomment for Rviz -->
    </visual>
    <collision>
      <origin rpy="0 0 0" xyz="0 0 0.09075"/>
      <geometry>
        <mesh filename="package://rc_car/meshes/Chassis.dae"/>
      </geometry>
    </collision>
    <inertial>
      <mass value="1"/>
      <inertia ixx="0.00414500685" ixy="0.0" ixz="0.0" iyy="0.01911488783" iyz="0.0" izz="0.02164626315"/>
      <origin rpy="0 0 0" xyz="0 0 0.088381"/>
    </inertial>
  </link>
  <gazebo reference="chassis">
    <material>Gazebo/Orange</material>
  </gazebo>
  <!-- Dummy Joint -->
  <joint name="dummy_joint" type="fixed">
    <parent link="dummy"/>
    <child link="chassis"/>
  </joint>
  <!-- Wheel Definition -->
  <!-- Hokuyo Laser Scanner -->
  <link name="laser_link">
    <visual>
      <geometry>
        <cylinder length=".02" radius=".05"/>
      </geometry>
      <origin rpy="0 0 0" xyz="0 0 0 "/>
    </visual>
    <collision>
      <geometry>
        <cylinder length=".02" radius=".05"/>
      </geometry>
      <origin rpy="0 0 0" xyz="0 0 0"/>
    </collision>
    <inertial>
      <mass value=".00001"/>
      <origin rpy="0 0 0" xyz="0 0 0"/>
      <inertia ixx=".000001" ixy="0" ixz="0" iyy=".000001" iyz="0" izz=".000001"/>
    </inertial>
  </link>
  <joint name="laser_joint" type="fixed">
    <parent link="chassis"/>
    <child link="laser_link"/>
    <origin rpy="0 0 0" xyz="0 0 0.15075"/>
    <axis rpy="0 0 0" xyz="0 0 1"/>
  </joint>
  <gazebo reference="laser_link">
    <material>Gazebo/Grey</material>
  </gazebo>
  <!-- Calling Wheel Macro -->
  <link name="front_right_wheel">
    <visual>
      <geometry>
        <mesh filename="package://rc_car/meshes/Wheel.dae"/>
      </geometry>
      <origin rpy="0 0 1.5707963267948966 " xyz="0 0 0"/>
      <!--  <material name="black"/> Uncomment for Rviz -->
    </visual>
    <collision>
      <geometry>
        <mesh filename="package://rc_car/meshes/Wheel.dae"/>
      </geometry>
      <origin rpy="0 0 1.5707963267948966" xyz="0 0 0"/>
    </collision>
    <inertial>
      <mass value="0.2"/>
      <inertia ixx="0.0002243658" ixy="0.0" ixz="0.0" iyy="0.00041873192200000004" iyz="0.0" izz="0.0002243658"/>
    </inertial>
  </link>
  <joint name="front_right_wheel_to_chassis" type="continuous">
    <axis rpy="0 0 0" xyz="0 1 0"/>
    <parent link="chassis"/>
    <child link="front_right_wheel"/>
    <origin rpy="0 0 0" xyz="0.14 -0.115 0.06075"/>
  </joint>
  <gazebo reference="front_right_wheel">
    <material>Gazebo/Black</material>
  </gazebo>
  <link name="rear_right_wheel">
    <visual>
      <geometry>
        <mesh filename="package://rc_car/meshes/Wheel.dae"/>
      </geometry>
      <origin rpy="0 0 1.5707963267948966 " xyz="0 0 0"/>
      <!--  <material name="black"/> Uncomment for Rviz -->
    </visual>
    <collision>
      <geometry>
        <mesh filename="package://rc_car/meshes/Wheel.dae"/>
      </geometry>
      <origin rpy="0 0 1.5707963267948966" xyz="0 0 0"/>
    </collision>
    <inertial>
      <mass value="0.2"/>
      <inertia ixx="0.0002243658" ixy="0.0" ixz="0.0" iyy="0.00041873192200000004" iyz="0.0" izz="0.0002243658"/>
    </inertial>
  </link>
  <joint name="rear_right_wheel_to_chassis" type="continuous">
    <axis rpy="0 0 0" xyz="0 1 0"/>
    <parent link="chassis"/>
    <child link="rear_right_wheel"/>
    <origin rpy="0 0 0" xyz="-0.14 -0.115 0.06075"/>
  </joint>
  <gazebo reference="rear_right_wheel">
    <material>Gazebo/Black</material>
  </gazebo>
  <link name="front_left_wheel">
    <visual>
      <geometry>
        <mesh filename="package://rc_car/meshes/Wheel.dae"/>
      </geometry>
      <origin rpy="0 0 1.5707963267948966 " xyz="0 0 0"/>
      <!--  <material name="black"/> Uncomment for Rviz -->
    </visual>
    <collision>
      <geometry>
        <mesh filename="package://rc_car/meshes/Wheel.dae"/>
      </geometry>
      <origin rpy="0 0 1.5707963267948966" xyz="0 0 0"/>
    </collision>
    <inertial>
      <mass value="0.2"/>
      <inertia ixx="0.0002243658" ixy="0.0" ixz="0.0" iyy="0.00041873192200000004" iyz="0.0" izz="0.0002243658"/>
    </inertial>
  </link>
  <joint name="front_left_wheel_to_chassis" type="continuous">
    <axis rpy="0 0 0" xyz="0 1 0"/>
    <parent link="chassis"/>
    <child link="front_left_wheel"/>
    <origin rpy="0 0 0" xyz="0.14 0.115 0.06075"/>
  </joint>
  <gazebo reference="front_left_wheel">
    <material>Gazebo/Black</material>
  </gazebo>
  <link name="rear_left_wheel">
    <visual>
      <geometry>
        <mesh filename="package://rc_car/meshes/Wheel.dae"/>
      </geometry>
      <origin rpy="0 0 1.5707963267948966 " xyz="0 0 0"/>
      <!--  <material name="black"/> Uncomment for Rviz -->
    </visual>
    <collision>
      <geometry>
        <mesh filename="package://rc_car/meshes/Wheel.dae"/>
      </geometry>
      <origin rpy="0 0 1.5707963267948966" xyz="0 0 0"/>
    </collision>
    <inertial>
      <mass value="0.2"/>
      <inertia ixx="0.0002243658" ixy="0.0" ixz="0.0" iyy="0.00041873192200000004" iyz="0.0" izz="0.0002243658"/>
    </inertial>
  </link>
  <joint name="rear_left_wheel_to_chassis" type="continuous">
    <axis rpy="0 0 0" xyz="0 1 0"/>
    <parent link="chassis"/>
    <child link="rear_left_wheel"/>
    <origin rpy="0 0 0" xyz="-0.14 0.115 0.06075"/>
  </joint>
  <gazebo reference="rear_left_wheel">
    <material>Gazebo/Black</material>
  </gazebo>
  <!-- Differential drive plugin 

 <gazebo>
  <plugin name="differential_drive_controller" filename="libgazebo_ros_diff_drive.so">
    <leftJoint>rear_left_wheel_to_chassis</leftJoint>
    <rightJoint>rear_right_wheel_to_chassis</rightJoint>
    <robotBaseFrame>chassis</robotBaseFrame>
    <wheelSeparation>${ch_w}</wheelSeparation>
    <wheelDiameter>${wheel_dia}</wheelDiameter>
    <commandTopic>cmd_vel</commandTopic>
    <odometryTopic>odom</odometryTopic>
    <odometryFrame>odom</odometryFrame>
    <publishWheelJointState>false</publishWheelJointState>
    <alwaysOn>true</alwaysOn>
    <legacyMode>false</legacyMode>
    <updateRate>40</updateRate>
    <wheelTorque>5</wheelTorque>
    <odometrySource>world</odometrySource>
    <publishWheelTF>false</publishWheelTF>
    <wheelAcceleration>0</wheelAcceleration>
    <rosDebugLevel>na</rosDebugLevel>
    <publishOdomTF>true</publishOdomTF>
    <publishTf>true</publishTf>
  </plugin>
 </gazebo>

-->
  <!-- Skid Steer plugin -->
  <gazebo>
    <plugin filename="libgazebo_ros_skid_steer_drive.so" name="skid_steer_drive_controller">
      <updateRate>100.0</updateRate>
      <robotNamespace>/</robotNamespace>
      <commandTopic>cmd_vel</commandTopic>
      <leftFrontJoint>front_left_wheel_to_chassis</leftFrontJoint>
      <rightFrontJoint>front_right_wheel_to_chassis</rightFrontJoint>
      <leftRearJoint>rear_left_wheel_to_chassis</leftRearJoint>
      <rightRearJoint>rear_right_wheel_to_chassis</rightRearJoint>
      <wheelSeparation>0.2</wheelSeparation>
      <wheelDiameter>0.1215</wheelDiameter>
      <robotBaseFrame>chassis</robotBaseFrame>
      <torque>5</torque>
      <odometryFrame>odom</odometryFrame>
      <odometryTopic>odom</odometryTopic>
      <topicName>cmd_vel</topicName>
      <broadcastTF>true</broadcastTF>
      <covariance_yaw>0.01</covariance_yaw>
      <covariance_y>0.0001</covariance_y>
      <covariance_x>0.0001</covariance_x>
    </plugin>
  </gazebo>
  <!-- Joint State Publisher -->
  <gazebo>
    <plugin filename="libgazebo_ros_joint_state_publisher.so" name="joint_state_publisher">
      <jointName>front_right_wheel_to_chassis,front_left_wheel_to_chassis,rear_right_wheel_to_chassis,rear_left_wheel_to_chassis</jointName>
      <updateRate>100</updateRate>
    </plugin>
  </gazebo>
  <!-- Laser Scanner definition -->
  <gazebo reference="laser_link">
    <sensor name="hokuyo" type="gpu_ray">
      <pose>0 0 0 0 0 0</pose>
      <visualize>true</visualize>
      <update_rate>40</update_rate>
      <ray>
        <scan>
          <horizontal>
            <samples>720</samples>
            <resolution>1</resolution>
            <min_angle>-1.570796</min_angle>
            <max_angle>1.570796</max_angle>
          </horizontal>
        </scan>
        <range>
          <min>0.10</min>
          <max>30.0</max>
          <resolution>0.01</resolution>
        </range>
      </ray>
      <plugin filename="libgazebo_ros_gpu_laser.so" name="gpu_laser">
        <topicName>/scan</topicName>
        <frameName>laser_link</frameName>
      </plugin>
    </sensor>
  </gazebo>
</robot>

